<?xml version="1.0" ?>
<robot name="robot_arm" xmlns:xacro="http://www.ros.org/wiki/xacro">

<xacro:include filename="$(find robot_arm_description)/urdf/materials.xacro" />
<xacro:include filename="$(find robot_arm_description)/urdf/robot_arm.trans" />
<xacro:include filename="$(find robot_arm_description)/urdf/robot_arm.gazebo" />
<link name="base_link">
  <inertial>
    <origin rpy="0 0 0" xyz="0.0020664042300333053 6.466553198827756e-10 0.02419226403185804"/>
    <mass value="0.16728828356549438"/>
    <inertia ixx="0.000174" ixy="-0.0" ixz="-7e-06" iyy="0.000194" iyz="0.0" izz="0.000278"/>
  </inertial>
  <visual>
    <origin rpy="0 0 0" xyz="0 0 0"/>
    <geometry>
      <mesh filename="package://robot_arm_description/meshes/base_link.stl" scale="0.001 0.001 0.001"/>
    </geometry>
    <material name="silver"/>
  </visual>
  <collision>
    <origin rpy="0 0 0" xyz="0 0 0"/>
    <geometry>
      <mesh filename="package://robot_arm_description/meshes/base_link.stl" scale="0.001 0.001 0.001"/>
    </geometry>
  </collision>
</link>

<link name="tool_1">
  <inertial>
    <origin rpy="0 0 0" xyz="0.029681331473707738 0.005034683436302485 0.003678054770134831"/>
    <mass value="0.03200159540129433"/>
    <inertia ixx="6e-06" ixy="-3e-06" ixz="-1e-06" iyy="1.3e-05" iyz="0.0" izz="1.5e-05"/>
  </inertial>
  <visual>
    <origin rpy="0 0 0" xyz="-0.012177 0.00285 -0.266299"/>
    <geometry>
      <mesh filename="package://robot_arm_description/meshes/tool_1.stl" scale="0.001 0.001 0.001"/>
    </geometry>
    <material name="silver"/>
  </visual>
  <collision>
    <origin rpy="0 0 0" xyz="-0.012177 0.00285 -0.266299"/>
    <geometry>
      <mesh filename="package://robot_arm_description/meshes/tool_1.stl" scale="0.001 0.001 0.001"/>
    </geometry>
  </collision>
</link>

<link name="wrist_1">
  <inertial>
    <origin rpy="0 0 0" xyz="0.010246135859655846 -0.003065519867974221 0.017362349593195214"/>
    <mass value="0.03047143481755528"/>
    <inertia ixx="5e-06" ixy="0.0" ixz="-1e-06" iyy="7e-06" iyz="0.0" izz="5e-06"/>
  </inertial>
  <visual>
    <origin rpy="0 0 0" xyz="0.004157 -0.0125 -0.242894"/>
    <geometry>
      <mesh filename="package://robot_arm_description/meshes/wrist_1.stl" scale="0.001 0.001 0.001"/>
    </geometry>
    <material name="silver"/>
  </visual>
  <collision>
    <origin rpy="0 0 0" xyz="0.004157 -0.0125 -0.242894"/>
    <geometry>
      <mesh filename="package://robot_arm_description/meshes/wrist_1.stl" scale="0.001 0.001 0.001"/>
    </geometry>
  </collision>
</link>

<link name="lower_arm_1">
  <inertial>
    <origin rpy="0 0 0" xyz="0.021975491384407124 0.016711488741899205 0.021952022901357227"/>
    <mass value="0.11769779065313278"/>
    <inertia ixx="8e-05" ixy="1e-05" ixz="-5.2e-05" iyy="0.000125" iyz="1e-05" izz="8e-05"/>
  </inertial>
  <visual>
    <origin rpy="0 0 0" xyz="0.072534 -0.0018 -0.181729"/>
    <geometry>
      <mesh filename="package://robot_arm_description/meshes/lower_arm_1.stl" scale="0.001 0.001 0.001"/>
    </geometry>
    <material name="silver"/>
  </visual>
  <collision>
    <origin rpy="0 0 0" xyz="0.072534 -0.0018 -0.181729"/>
    <geometry>
      <mesh filename="package://robot_arm_description/meshes/lower_arm_1.stl" scale="0.001 0.001 0.001"/>
    </geometry>
  </collision>
</link>

<link name="upper_arm_1">
  <inertial>
    <origin rpy="0 0 0" xyz="-0.041522617129985125 -0.007768202679353794 0.04133826671607861"/>
    <mass value="0.5054466041808731"/>
    <inertia ixx="0.000474" ixy="1e-06" ixz="0.000396" iyy="0.000903" iyz="-1e-06" izz="0.000463"/>
  </inertial>
  <visual>
    <origin rpy="0 0 0" xyz="-0.012319 -0.0018 -0.096876"/>
    <geometry>
      <mesh filename="package://robot_arm_description/meshes/upper_arm_1.stl" scale="0.001 0.001 0.001"/>
    </geometry>
    <material name="silver"/>
  </visual>
  <collision>
    <origin rpy="0 0 0" xyz="-0.012319 -0.0018 -0.096876"/>
    <geometry>
      <mesh filename="package://robot_arm_description/meshes/upper_arm_1.stl" scale="0.001 0.001 0.001"/>
    </geometry>
  </collision>
</link>

<link name="waist_1">
  <inertial>
    <origin rpy="0 0 0" xyz="0.0032447569034795187 0.013877745202582331 0.022630817273136372"/>
    <mass value="0.13143588308849458"/>
    <inertia ixx="9e-05" ixy="-4e-06" ixz="-1.3e-05" iyy="9.1e-05" iyz="-1.7e-05" izz="9.6e-05"/>
  </inertial>
  <visual>
    <origin rpy="0 0 0" xyz="0.0016 -0.0 -0.0566"/>
    <geometry>
      <mesh filename="package://robot_arm_description/meshes/waist_1.stl" scale="0.001 0.001 0.001"/>
    </geometry>
    <material name="silver"/>
  </visual>
  <collision>
    <origin rpy="0 0 0" xyz="0.0016 -0.0 -0.0566"/>
    <geometry>
      <mesh filename="package://robot_arm_description/meshes/waist_1.stl" scale="0.001 0.001 0.001"/>
    </geometry>
  </collision>
</link>

<link name="gear_l_1">
  <inertial>
    <origin rpy="0 0 0" xyz="0.0005899134384872579 0.005667053218810088 0.0020002649471745904"/>
    <mass value="0.0033099589734535495"/>
    <inertia ixx="0.0" ixy="0.0" ixz="-0.0" iyy="0.0" iyz="-0.0" izz="1e-06"/>
  </inertial>
  <visual>
    <origin rpy="0 0 0" xyz="-0.050177 -0.01505 -0.280299"/>
    <geometry>
      <mesh filename="package://robot_arm_description/meshes/gear_l_1.stl" scale="0.001 0.001 0.001"/>
    </geometry>
    <material name="silver"/>
  </visual>
  <collision>
    <origin rpy="0 0 0" xyz="-0.050177 -0.01505 -0.280299"/>
    <geometry>
      <mesh filename="package://robot_arm_description/meshes/gear_l_1.stl" scale="0.001 0.001 0.001"/>
    </geometry>
  </collision>
</link>

<link name="gear_r_1">
  <inertial>
    <origin rpy="0 0 0" xyz="0.0005979538243359381 -0.005579192111270146 0.002000264947174646"/>
    <mass value="0.0034076811371724575"/>
    <inertia ixx="0.0" ixy="-0.0" ixz="-0.0" iyy="0.0" iyz="0.0" izz="1e-06"/>
  </inertial>
  <visual>
    <origin rpy="0 0 0" xyz="-0.050177 0.01185 -0.280299"/>
    <geometry>
      <mesh filename="package://robot_arm_description/meshes/gear_r_1.stl" scale="0.001 0.001 0.001"/>
    </geometry>
    <material name="silver"/>
  </visual>
  <collision>
    <origin rpy="0 0 0" xyz="-0.050177 0.01185 -0.280299"/>
    <geometry>
      <mesh filename="package://robot_arm_description/meshes/gear_r_1.stl" scale="0.001 0.001 0.001"/>
    </geometry>
  </collision>
</link>

<link name="passiv_link_left_1">
  <inertial>
    <origin rpy="0 0 0" xyz="-7.344014011954891e-05 -0.015500139171575316 0.0020002649471748124"/>
    <mass value="0.0010304035130082416"/>
    <inertia ixx="0.0" ixy="-0.0" ixz="-0.0" iyy="0.0" iyz="0.0" izz="0.0"/>
  </inertial>
  <visual>
    <origin rpy="0 0 0" xyz="-0.070326 -0.037154 -0.280299"/>
    <geometry>
      <mesh filename="package://robot_arm_description/meshes/passiv_link_left_1.stl" scale="0.001 0.001 0.001"/>
    </geometry>
    <material name="silver"/>
  </visual>
  <collision>
    <origin rpy="0 0 0" xyz="-0.070326 -0.037154 -0.280299"/>
    <geometry>
      <mesh filename="package://robot_arm_description/meshes/passiv_link_left_1.stl" scale="0.001 0.001 0.001"/>
    </geometry>
  </collision>
</link>

<link name="finger_l_1">
  <inertial>
    <origin rpy="0 0 0" xyz="0.0264996913257496 -0.006416941777612359 -0.00424973505282511"/>
    <mass value="0.006962678719455662"/>
    <inertia ixx="0.0" ixy="0.0" ixz="0.0" iyy="2e-06" iyz="0.0" izz="2e-06"/>
  </inertial>
  <visual>
    <origin rpy="0 0 0" xyz="-0.050097 -0.0458 -0.280299"/>
    <geometry>
      <mesh filename="package://robot_arm_description/meshes/finger_l_1.stl" scale="0.001 0.001 0.001"/>
    </geometry>
    <material name="silver"/>
  </visual>
  <collision>
    <origin rpy="0 0 0" xyz="-0.050097 -0.0458 -0.280299"/>
    <geometry>
      <mesh filename="package://robot_arm_description/meshes/finger_l_1.stl" scale="0.001 0.001 0.001"/>
    </geometry>
  </collision>
</link>

<link name="passive_link_right_1">
  <inertial>
    <origin rpy="0 0 0" xyz="7.392196295702425e-05 0.015499801346418072 0.002000264947174535"/>
    <mass value="0.0010304035130082416"/>
    <inertia ixx="0.0" ixy="-0.0" ixz="-0.0" iyy="0.0" iyz="0.0" izz="0.0"/>
  </inertial>
  <visual>
    <origin rpy="0 0 0" xyz="-0.070876 0.03521 -0.280299"/>
    <geometry>
      <mesh filename="package://robot_arm_description/meshes/passive_link_right_1.stl" scale="0.001 0.001 0.001"/>
    </geometry>
    <material name="silver"/>
  </visual>
  <collision>
    <origin rpy="0 0 0" xyz="-0.070876 0.03521 -0.280299"/>
    <geometry>
      <mesh filename="package://robot_arm_description/meshes/passive_link_right_1.stl" scale="0.001 0.001 0.001"/>
    </geometry>
  </collision>
</link>

<link name="finger_r_1">
  <inertial>
    <origin rpy="0 0 0" xyz="0.02684411509474962 0.00478045272417623 -0.0042497350528256095"/>
    <mass value="0.0069626787194557215"/>
    <inertia ixx="0.0" ixy="-0.0" ixz="-0.0" iyy="2e-06" iyz="0.0" izz="2e-06"/>
  </inertial>
  <visual>
    <origin rpy="0 0 0" xyz="-0.050154 0.0426 -0.280299"/>
    <geometry>
      <mesh filename="package://robot_arm_description/meshes/finger_r_1.stl" scale="0.001 0.001 0.001"/>
    </geometry>
    <material name="silver"/>
  </visual>
  <collision>
    <origin rpy="0 0 0" xyz="-0.050154 0.0426 -0.280299"/>
    <geometry>
      <mesh filename="package://robot_arm_description/meshes/finger_r_1.stl" scale="0.001 0.001 0.001"/>
    </geometry>
  </collision>
</link>

<joint name="pitch" type="continuous">
  <origin rpy="0 0 0" xyz="0.016334 -0.01535 0.023405"/>
  <parent link="wrist_1"/>
  <child link="tool_1"/>
  <axis xyz="0.0 -1.0 -0.0"/>
</joint>

<joint name="roll" type="continuous">
  <origin rpy="0 0 0" xyz="0.068377 0.0107 0.061165"/>
  <parent link="lower_arm_1"/>
  <child link="wrist_1"/>
  <axis xyz="0.707107 -0.0 0.707107"/>
</joint>

<joint name="elbow" type="continuous">
  <origin rpy="0 0 0" xyz="-0.084853 0.0 0.084853"/>
  <parent link="upper_arm_1"/>
  <child link="lower_arm_1"/>
  <axis xyz="-0.0 1.0 0.0"/>
</joint>

<joint name="shoulder" type="continuous">
  <origin rpy="0 0 0" xyz="0.013919 0.0018 0.040276"/>
  <parent link="waist_1"/>
  <child link="upper_arm_1"/>
  <axis xyz="-0.0 -1.0 -0.0"/>
</joint>

<joint name="base" type="continuous">
  <origin rpy="0 0 0" xyz="-0.0016 0.0 0.0566"/>
  <parent link="base_link"/>
  <child link="waist_1"/>
  <axis xyz="0.0 0.0 1.0"/>
</joint>

<joint name="finger_gear_left" type="revolute">
  <origin rpy="0 0 0" xyz="0.038 0.0179 0.014"/>
  <parent link="tool_1"/>
  <child link="gear_l_1"/>
  <axis xyz="0.0 -0.0 1.0"/>
  <limit effort="100" lower="-1.570796" upper="0.0" velocity="100"/>
</joint>

<joint name="finger_gear_right" type="continuous">
  <origin rpy="0 0 0" xyz="0.038 -0.009 0.014"/>
  <parent link="tool_1"/>
  <child link="gear_r_1"/>
  <axis xyz="0.0 -0.0 1.0"/>
</joint>

<joint name="l2f_left" type="revolute">
  <origin rpy="0 0 0" xyz="0.020229 -0.008646 0.0"/>
  <parent link="finger_l_1"/>
  <child link="passiv_link_left_1"/>
  <axis xyz="-0.0 0.0 1.0"/>
  <limit effort="100" lower="-1.570796" upper="0.0" velocity="100"/>
</joint>

<joint name="f2g_left" type="revolute">
  <origin rpy="0 0 0" xyz="-8e-05 0.03075 0.0"/>
  <parent link="gear_l_1"/>
  <child link="finger_l_1"/>
  <axis xyz="0.0 0.0 1.0"/>
  <limit effort="100" lower="0.0" upper="1.570796" velocity="100"/>
</joint>

<joint name="f2l_right" type="revolute">
  <origin rpy="0 0 0" xyz="0.020722 0.00739 0.0"/>
  <parent link="finger_r_1"/>
  <child link="passive_link_right_1"/>
  <axis xyz="-0.0 0.0 -1.0"/>
  <limit effort="100" lower="-1.570796" upper="0.0" velocity="100"/>
</joint>

<joint name="f2g_right" type="revolute">
  <origin rpy="0 0 0" xyz="-2.3e-05 -0.03075 0.0"/>
  <parent link="gear_r_1"/>
  <child link="finger_r_1"/>
  <axis xyz="0.0 -0.0 1.0"/>
  <limit effort="100" lower="-1.570796" upper="0.0" velocity="100"/>
</joint>

</robot>
